Internal Server Error: /api/products/
Traceback (most recent call last):
  File "/home/adane/snap/code/190/.local/share/virtualenvs/Backend-OTU7wIHD/lib/python3.12/site-packages/django/db/backends/utils.py", line 105, in _execute
    return self.cursor.execute(sql, params)
           ^^^^^^^^^^^^^^^^^^^^^^^^^^^^^^^^
psycopg2.errors.NotNullViolation: null value in column "category_id" of relation "products_product" violates not-null constraint
DETAIL:  Failing row contains (43a7f6c6-3978-4bd1-aeb0-d0c1c9845a91, SKU-001, Smartphone X, 500.00, 20.00, 600.00, 0, t, Latest model with advanced features., , [], , {}, , https://example.com/image.jpg, ["https://example.com/image1.jpg", "https://example.com/image2.j..., ["Black", "White"], ["64GB", "128GB"], 0, 0, 0, 2025-05-04 08:36:27.502801+00, 2025-05-04 08:36:27.502859+00, null, 06cbdc10-c1a0-4e24-8744-dd237b65be43).


The above exception was the direct cause of the following exception:

Traceback (most recent call last):
  File "/home/adane/snap/code/190/.local/share/virtualenvs/Backend-OTU7wIHD/lib/python3.12/site-packages/django/core/handlers/exception.py", line 55, in inner
    response = get_response(request)
               ^^^^^^^^^^^^^^^^^^^^^
  File "/home/adane/snap/code/190/.local/share/virtualenvs/Backend-OTU7wIHD/lib/python3.12/site-packages/django/core/handlers/base.py", line 197, in _get_response
    response = wrapped_callback(request, *callback_args, **callback_kwargs)
               ^^^^^^^^^^^^^^^^^^^^^^^^^^^^^^^^^^^^^^^^^^^^^^^^^^^^^^^^^^^^
  File "/home/adane/snap/code/190/.local/share/virtualenvs/Backend-OTU7wIHD/lib/python3.12/site-packages/django/views/decorators/csrf.py", line 65, in _view_wrapper
    return view_func(request, *args, **kwargs)
           ^^^^^^^^^^^^^^^^^^^^^^^^^^^^^^^^^^^
  File "/home/adane/snap/code/190/.local/share/virtualenvs/Backend-OTU7wIHD/lib/python3.12/site-packages/rest_framework/viewsets.py", line 125, in view
    return self.dispatch(request, *args, **kwargs)
           ^^^^^^^^^^^^^^^^^^^^^^^^^^^^^^^^^^^^^^^
  File "/home/adane/snap/code/190/.local/share/virtualenvs/Backend-OTU7wIHD/lib/python3.12/site-packages/rest_framework/views.py", line 515, in dispatch
    response = self.handle_exception(exc)
               ^^^^^^^^^^^^^^^^^^^^^^^^^^
  File "/home/adane/snap/code/190/.local/share/virtualenvs/Backend-OTU7wIHD/lib/python3.12/site-packages/rest_framework/views.py", line 475, in handle_exception
    self.raise_uncaught_exception(exc)
  File "/home/adane/snap/code/190/.local/share/virtualenvs/Backend-OTU7wIHD/lib/python3.12/site-packages/rest_framework/views.py", line 486, in raise_uncaught_exception
    raise exc
  File "/home/adane/snap/code/190/.local/share/virtualenvs/Backend-OTU7wIHD/lib/python3.12/site-packages/rest_framework/views.py", line 512, in dispatch
    response = handler(request, *args, **kwargs)
               ^^^^^^^^^^^^^^^^^^^^^^^^^^^^^^^^^
  File "/home/adane/snap/code/190/.local/share/virtualenvs/Backend-OTU7wIHD/lib/python3.12/site-packages/rest_framework/mixins.py", line 19, in create
    self.perform_create(serializer)
  File "/home/adane/Repository/ConnectX/Backend/connectx_backend/products/views.py", line 191, in perform_create
    serializer.save(owner=self.request.user.tenant)
  File "/home/adane/snap/code/190/.local/share/virtualenvs/Backend-OTU7wIHD/lib/python3.12/site-packages/rest_framework/serializers.py", line 210, in save
    self.instance = self.create(validated_data)
                    ^^^^^^^^^^^^^^^^^^^^^^^^^^^
  File "/home/adane/snap/code/190/.local/share/virtualenvs/Backend-OTU7wIHD/lib/python3.12/site-packages/rest_framework/serializers.py", line 991, in create
    instance = ModelClass._default_manager.create(**validated_data)
               ^^^^^^^^^^^^^^^^^^^^^^^^^^^^^^^^^^^^^^^^^^^^^^^^^^^^
  File "/home/adane/snap/code/190/.local/share/virtualenvs/Backend-OTU7wIHD/lib/python3.12/site-packages/django/db/models/manager.py", line 87, in manager_method
    return getattr(self.get_queryset(), name)(*args, **kwargs)
           ^^^^^^^^^^^^^^^^^^^^^^^^^^^^^^^^^^^^^^^^^^^^^^^^^^^
  File "/home/adane/snap/code/190/.local/share/virtualenvs/Backend-OTU7wIHD/lib/python3.12/site-packages/django/db/models/query.py", line 663, in create
    obj.save(force_insert=True, using=self.db)
  File "/home/adane/Repository/ConnectX/Backend/connectx_backend/products/models.py", line 41, in save
    super().save(*args, **kwargs)
  File "/home/adane/snap/code/190/.local/share/virtualenvs/Backend-OTU7wIHD/lib/python3.12/site-packages/django/db/models/base.py", line 902, in save
    self.save_base(
  File "/home/adane/snap/code/190/.local/share/virtualenvs/Backend-OTU7wIHD/lib/python3.12/site-packages/django/db/models/base.py", line 1008, in save_base
    updated = self._save_table(
              ^^^^^^^^^^^^^^^^^
  File "/home/adane/snap/code/190/.local/share/virtualenvs/Backend-OTU7wIHD/lib/python3.12/site-packages/django/db/models/base.py", line 1169, in _save_table
    results = self._do_insert(
              ^^^^^^^^^^^^^^^^
  File "/home/adane/snap/code/190/.local/share/virtualenvs/Backend-OTU7wIHD/lib/python3.12/site-packages/django/db/models/base.py", line 1210, in _do_insert
    return manager._insert(
           ^^^^^^^^^^^^^^^^
  File "/home/adane/snap/code/190/.local/share/virtualenvs/Backend-OTU7wIHD/lib/python3.12/site-packages/django/db/models/manager.py", line 87, in manager_method
    return getattr(self.get_queryset(), name)(*args, **kwargs)
           ^^^^^^^^^^^^^^^^^^^^^^^^^^^^^^^^^^^^^^^^^^^^^^^^^^^
  File "/home/adane/snap/code/190/.local/share/virtualenvs/Backend-OTU7wIHD/lib/python3.12/site-packages/django/db/models/query.py", line 1854, in _insert
    return query.get_compiler(using=using).execute_sql(returning_fields)
           ^^^^^^^^^^^^^^^^^^^^^^^^^^^^^^^^^^^^^^^^^^^^^^^^^^^^^^^^^^^^^
  File "/home/adane/snap/code/190/.local/share/virtualenvs/Backend-OTU7wIHD/lib/python3.12/site-packages/django/db/models/sql/compiler.py", line 1881, in execute_sql
    cursor.execute(sql, params)
  File "/home/adane/snap/code/190/.local/share/virtualenvs/Backend-OTU7wIHD/lib/python3.12/site-packages/django/db/backends/utils.py", line 122, in execute
    return super().execute(sql, params)
           ^^^^^^^^^^^^^^^^^^^^^^^^^^^^
  File "/home/adane/snap/code/190/.local/share/virtualenvs/Backend-OTU7wIHD/lib/python3.12/site-packages/django/db/backends/utils.py", line 79, in execute
    return self._execute_with_wrappers(
           ^^^^^^^^^^^^^^^^^^^^^^^^^^^^
  File "/home/adane/snap/code/190/.local/share/virtualenvs/Backend-OTU7wIHD/lib/python3.12/site-packages/django/db/backends/utils.py", line 92, in _execute_with_wrappers
    return executor(sql, params, many, context)
           ^^^^^^^^^^^^^^^^^^^^^^^^^^^^^^^^^^^^
  File "/home/adane/snap/code/190/.local/share/virtualenvs/Backend-OTU7wIHD/lib/python3.12/site-packages/django/db/backends/utils.py", line 100, in _execute
    with self.db.wrap_database_errors:
  File "/home/adane/snap/code/190/.local/share/virtualenvs/Backend-OTU7wIHD/lib/python3.12/site-packages/django/db/utils.py", line 91, in __exit__
    raise dj_exc_value.with_traceback(traceback) from exc_value
  File "/home/adane/snap/code/190/.local/share/virtualenvs/Backend-OTU7wIHD/lib/python3.12/site-packages/django/db/backends/utils.py", line 105, in _execute
    return self.cursor.execute(sql, params)
           ^^^^^^^^^^^^^^^^^^^^^^^^^^^^^^^^
django.db.utils.IntegrityError: null value in column "category_id" of relation "products_product" violates not-null constraint
DETAIL:  Failing row contains (43a7f6c6-3978-4bd1-aeb0-d0c1c9845a91, SKU-001, Smartphone X, 500.00, 20.00, 600.00, 0, t, Latest model with advanced features., , [], , {}, , https://example.com/image.jpg, ["https://example.com/image1.jpg", "https://example.com/image2.j..., ["Black", "White"], ["64GB", "128GB"], 0, 0, 0, 2025-05-04 08:36:27.502801+00, 2025-05-04 08:36:27.502859+00, null, 06cbdc10-c1a0-4e24-8744-dd237b65be43).

"POST /api/products/ HTTP/1.1" 500 32068
Internal Server Error: /api/products/
Traceback (most recent call last):
  File "/home/adane/snap/code/190/.local/share/virtualenvs/Backend-OTU7wIHD/lib/python3.12/site-packages/django/core/handlers/exception.py", line 55, in inner
    response = get_response(request)
               ^^^^^^^^^^^^^^^^^^^^^
  File "/home/adane/snap/code/190/.local/share/virtualenvs/Backend-OTU7wIHD/lib/python3.12/site-packages/django/core/handlers/base.py", line 197, in _get_response
    response = wrapped_callback(request, *callback_args, **callback_kwargs)
               ^^^^^^^^^^^^^^^^^^^^^^^^^^^^^^^^^^^^^^^^^^^^^^^^^^^^^^^^^^^^
  File "/home/adane/snap/code/190/.local/share/virtualenvs/Backend-OTU7wIHD/lib/python3.12/site-packages/django/views/decorators/csrf.py", line 65, in _view_wrapper
    return view_func(request, *args, **kwargs)
           ^^^^^^^^^^^^^^^^^^^^^^^^^^^^^^^^^^^
  File "/home/adane/snap/code/190/.local/share/virtualenvs/Backend-OTU7wIHD/lib/python3.12/site-packages/rest_framework/viewsets.py", line 125, in view
    return self.dispatch(request, *args, **kwargs)
           ^^^^^^^^^^^^^^^^^^^^^^^^^^^^^^^^^^^^^^^
  File "/home/adane/snap/code/190/.local/share/virtualenvs/Backend-OTU7wIHD/lib/python3.12/site-packages/rest_framework/views.py", line 515, in dispatch
    response = self.handle_exception(exc)
               ^^^^^^^^^^^^^^^^^^^^^^^^^^
  File "/home/adane/snap/code/190/.local/share/virtualenvs/Backend-OTU7wIHD/lib/python3.12/site-packages/rest_framework/views.py", line 475, in handle_exception
    self.raise_uncaught_exception(exc)
  File "/home/adane/snap/code/190/.local/share/virtualenvs/Backend-OTU7wIHD/lib/python3.12/site-packages/rest_framework/views.py", line 486, in raise_uncaught_exception
    raise exc
  File "/home/adane/snap/code/190/.local/share/virtualenvs/Backend-OTU7wIHD/lib/python3.12/site-packages/rest_framework/views.py", line 512, in dispatch
    response = handler(request, *args, **kwargs)
               ^^^^^^^^^^^^^^^^^^^^^^^^^^^^^^^^^
  File "/home/adane/snap/code/190/.local/share/virtualenvs/Backend-OTU7wIHD/lib/python3.12/site-packages/rest_framework/mixins.py", line 19, in create
    self.perform_create(serializer)
  File "/home/adane/Repository/ConnectX/Backend/connectx_backend/products/views.py", line 191, in perform_create
    serializer.save(owner=self.request.user.tenant)
  File "/home/adane/snap/code/190/.local/share/virtualenvs/Backend-OTU7wIHD/lib/python3.12/site-packages/rest_framework/serializers.py", line 210, in save
    self.instance = self.create(validated_data)
                    ^^^^^^^^^^^^^^^^^^^^^^^^^^^
  File "/home/adane/snap/code/190/.local/share/virtualenvs/Backend-OTU7wIHD/lib/python3.12/site-packages/rest_framework/serializers.py", line 977, in create
    raise_errors_on_nested_writes('create', self, validated_data)
  File "/home/adane/snap/code/190/.local/share/virtualenvs/Backend-OTU7wIHD/lib/python3.12/site-packages/rest_framework/serializers.py", line 842, in raise_errors_on_nested_writes
    assert not any(
           ^^^^^^^^
AssertionError: The `.create()` method does not support writable nested fields by default.
Write an explicit `.create()` method for serializer `products.serializers.ProductSerializer`, or set `read_only=True` on nested serializer fields.
"POST /api/products/ HTTP/1.1" 500 27049
Internal Server Error: /api/products/
Traceback (most recent call last):
  File "/home/adane/snap/code/190/.local/share/virtualenvs/Backend-OTU7wIHD/lib/python3.12/site-packages/django/db/backends/utils.py", line 105, in _execute
    return self.cursor.execute(sql, params)
           ^^^^^^^^^^^^^^^^^^^^^^^^^^^^^^^^
psycopg2.errors.NotNullViolation: null value in column "category_id" of relation "products_product" violates not-null constraint
DETAIL:  Failing row contains (a37d847e-cb5c-4c67-8fc9-24a63db7f180, SKU-001, Smartphone X, 500.00, 20.00, 600.00, 100, t, Latest model with advanced features., , [], , {}, , https://example.com/image.jpg, ["https://example.com/image1.jpg", "https://example.com/image2.j..., ["Black", "White"], ["64GB", "128GB"], 0, 0, 0, 2025-05-04 08:53:02.904994+00, 2025-05-04 08:53:02.905076+00, null, 06cbdc10-c1a0-4e24-8744-dd237b65be43).


The above exception was the direct cause of the following exception:

Traceback (most recent call last):
  File "/home/adane/snap/code/190/.local/share/virtualenvs/Backend-OTU7wIHD/lib/python3.12/site-packages/django/core/handlers/exception.py", line 55, in inner
    response = get_response(request)
               ^^^^^^^^^^^^^^^^^^^^^
  File "/home/adane/snap/code/190/.local/share/virtualenvs/Backend-OTU7wIHD/lib/python3.12/site-packages/django/core/handlers/base.py", line 197, in _get_response
    response = wrapped_callback(request, *callback_args, **callback_kwargs)
               ^^^^^^^^^^^^^^^^^^^^^^^^^^^^^^^^^^^^^^^^^^^^^^^^^^^^^^^^^^^^
  File "/home/adane/snap/code/190/.local/share/virtualenvs/Backend-OTU7wIHD/lib/python3.12/site-packages/django/views/decorators/csrf.py", line 65, in _view_wrapper
    return view_func(request, *args, **kwargs)
           ^^^^^^^^^^^^^^^^^^^^^^^^^^^^^^^^^^^
  File "/home/adane/snap/code/190/.local/share/virtualenvs/Backend-OTU7wIHD/lib/python3.12/site-packages/rest_framework/viewsets.py", line 125, in view
    return self.dispatch(request, *args, **kwargs)
           ^^^^^^^^^^^^^^^^^^^^^^^^^^^^^^^^^^^^^^^
  File "/home/adane/snap/code/190/.local/share/virtualenvs/Backend-OTU7wIHD/lib/python3.12/site-packages/rest_framework/views.py", line 515, in dispatch
    response = self.handle_exception(exc)
               ^^^^^^^^^^^^^^^^^^^^^^^^^^
  File "/home/adane/snap/code/190/.local/share/virtualenvs/Backend-OTU7wIHD/lib/python3.12/site-packages/rest_framework/views.py", line 475, in handle_exception
    self.raise_uncaught_exception(exc)
  File "/home/adane/snap/code/190/.local/share/virtualenvs/Backend-OTU7wIHD/lib/python3.12/site-packages/rest_framework/views.py", line 486, in raise_uncaught_exception
    raise exc
  File "/home/adane/snap/code/190/.local/share/virtualenvs/Backend-OTU7wIHD/lib/python3.12/site-packages/rest_framework/views.py", line 512, in dispatch
    response = handler(request, *args, **kwargs)
               ^^^^^^^^^^^^^^^^^^^^^^^^^^^^^^^^^
  File "/home/adane/snap/code/190/.local/share/virtualenvs/Backend-OTU7wIHD/lib/python3.12/site-packages/rest_framework/mixins.py", line 19, in create
    self.perform_create(serializer)
  File "/home/adane/Repository/ConnectX/Backend/connectx_backend/products/views.py", line 191, in perform_create
    serializer.save(owner=self.request.user.tenant,)
  File "/home/adane/snap/code/190/.local/share/virtualenvs/Backend-OTU7wIHD/lib/python3.12/site-packages/rest_framework/serializers.py", line 210, in save
    self.instance = self.create(validated_data)
                    ^^^^^^^^^^^^^^^^^^^^^^^^^^^
  File "/home/adane/snap/code/190/.local/share/virtualenvs/Backend-OTU7wIHD/lib/python3.12/site-packages/rest_framework/serializers.py", line 991, in create
    instance = ModelClass._default_manager.create(**validated_data)
               ^^^^^^^^^^^^^^^^^^^^^^^^^^^^^^^^^^^^^^^^^^^^^^^^^^^^
  File "/home/adane/snap/code/190/.local/share/virtualenvs/Backend-OTU7wIHD/lib/python3.12/site-packages/django/db/models/manager.py", line 87, in manager_method
    return getattr(self.get_queryset(), name)(*args, **kwargs)
           ^^^^^^^^^^^^^^^^^^^^^^^^^^^^^^^^^^^^^^^^^^^^^^^^^^^
  File "/home/adane/snap/code/190/.local/share/virtualenvs/Backend-OTU7wIHD/lib/python3.12/site-packages/django/db/models/query.py", line 663, in create
    obj.save(force_insert=True, using=self.db)
  File "/home/adane/Repository/ConnectX/Backend/connectx_backend/products/models.py", line 41, in save
    super().save(*args, **kwargs)
  File "/home/adane/snap/code/190/.local/share/virtualenvs/Backend-OTU7wIHD/lib/python3.12/site-packages/django/db/models/base.py", line 902, in save
    self.save_base(
  File "/home/adane/snap/code/190/.local/share/virtualenvs/Backend-OTU7wIHD/lib/python3.12/site-packages/django/db/models/base.py", line 1008, in save_base
    updated = self._save_table(
              ^^^^^^^^^^^^^^^^^
  File "/home/adane/snap/code/190/.local/share/virtualenvs/Backend-OTU7wIHD/lib/python3.12/site-packages/django/db/models/base.py", line 1169, in _save_table
    results = self._do_insert(
              ^^^^^^^^^^^^^^^^
  File "/home/adane/snap/code/190/.local/share/virtualenvs/Backend-OTU7wIHD/lib/python3.12/site-packages/django/db/models/base.py", line 1210, in _do_insert
    return manager._insert(
           ^^^^^^^^^^^^^^^^
  File "/home/adane/snap/code/190/.local/share/virtualenvs/Backend-OTU7wIHD/lib/python3.12/site-packages/django/db/models/manager.py", line 87, in manager_method
    return getattr(self.get_queryset(), name)(*args, **kwargs)
           ^^^^^^^^^^^^^^^^^^^^^^^^^^^^^^^^^^^^^^^^^^^^^^^^^^^
  File "/home/adane/snap/code/190/.local/share/virtualenvs/Backend-OTU7wIHD/lib/python3.12/site-packages/django/db/models/query.py", line 1854, in _insert
    return query.get_compiler(using=using).execute_sql(returning_fields)
           ^^^^^^^^^^^^^^^^^^^^^^^^^^^^^^^^^^^^^^^^^^^^^^^^^^^^^^^^^^^^^
  File "/home/adane/snap/code/190/.local/share/virtualenvs/Backend-OTU7wIHD/lib/python3.12/site-packages/django/db/models/sql/compiler.py", line 1881, in execute_sql
    cursor.execute(sql, params)
  File "/home/adane/snap/code/190/.local/share/virtualenvs/Backend-OTU7wIHD/lib/python3.12/site-packages/django/db/backends/utils.py", line 122, in execute
    return super().execute(sql, params)
           ^^^^^^^^^^^^^^^^^^^^^^^^^^^^
  File "/home/adane/snap/code/190/.local/share/virtualenvs/Backend-OTU7wIHD/lib/python3.12/site-packages/django/db/backends/utils.py", line 79, in execute
    return self._execute_with_wrappers(
           ^^^^^^^^^^^^^^^^^^^^^^^^^^^^
  File "/home/adane/snap/code/190/.local/share/virtualenvs/Backend-OTU7wIHD/lib/python3.12/site-packages/django/db/backends/utils.py", line 92, in _execute_with_wrappers
    return executor(sql, params, many, context)
           ^^^^^^^^^^^^^^^^^^^^^^^^^^^^^^^^^^^^
  File "/home/adane/snap/code/190/.local/share/virtualenvs/Backend-OTU7wIHD/lib/python3.12/site-packages/django/db/backends/utils.py", line 100, in _execute
    with self.db.wrap_database_errors:
  File "/home/adane/snap/code/190/.local/share/virtualenvs/Backend-OTU7wIHD/lib/python3.12/site-packages/django/db/utils.py", line 91, in __exit__
    raise dj_exc_value.with_traceback(traceback) from exc_value
  File "/home/adane/snap/code/190/.local/share/virtualenvs/Backend-OTU7wIHD/lib/python3.12/site-packages/django/db/backends/utils.py", line 105, in _execute
    return self.cursor.execute(sql, params)
           ^^^^^^^^^^^^^^^^^^^^^^^^^^^^^^^^
django.db.utils.IntegrityError: null value in column "category_id" of relation "products_product" violates not-null constraint
DETAIL:  Failing row contains (a37d847e-cb5c-4c67-8fc9-24a63db7f180, SKU-001, Smartphone X, 500.00, 20.00, 600.00, 100, t, Latest model with advanced features., , [], , {}, , https://example.com/image.jpg, ["https://example.com/image1.jpg", "https://example.com/image2.j..., ["Black", "White"], ["64GB", "128GB"], 0, 0, 0, 2025-05-04 08:53:02.904994+00, 2025-05-04 08:53:02.905076+00, null, 06cbdc10-c1a0-4e24-8744-dd237b65be43).

"POST /api/products/ HTTP/1.1" 500 32076
Internal Server Error: /api/products/
Traceback (most recent call last):
  File "/home/adane/snap/code/190/.local/share/virtualenvs/Backend-OTU7wIHD/lib/python3.12/site-packages/django/db/backends/utils.py", line 105, in _execute
    return self.cursor.execute(sql, params)
           ^^^^^^^^^^^^^^^^^^^^^^^^^^^^^^^^
psycopg2.errors.NotNullViolation: null value in column "category_id" of relation "products_product" violates not-null constraint
DETAIL:  Failing row contains (2990d0a3-ee9f-4eb1-9646-44874205013b, SKU-001, Smartphone X, 500.00, 20.00, 600.00, 100, t, Latest model with advanced features., , [], , {}, , https://example.com/image.jpg, ["https://example.com/image1.jpg", "https://example.com/image2.j..., ["Black", "White"], ["64GB", "128GB"], 0, 0, 0, 2025-05-04 08:54:21.611227+00, 2025-05-04 08:54:21.611279+00, null, 06cbdc10-c1a0-4e24-8744-dd237b65be43).


The above exception was the direct cause of the following exception:

Traceback (most recent call last):
  File "/home/adane/snap/code/190/.local/share/virtualenvs/Backend-OTU7wIHD/lib/python3.12/site-packages/django/core/handlers/exception.py", line 55, in inner
    response = get_response(request)
               ^^^^^^^^^^^^^^^^^^^^^
  File "/home/adane/snap/code/190/.local/share/virtualenvs/Backend-OTU7wIHD/lib/python3.12/site-packages/django/core/handlers/base.py", line 197, in _get_response
    response = wrapped_callback(request, *callback_args, **callback_kwargs)
               ^^^^^^^^^^^^^^^^^^^^^^^^^^^^^^^^^^^^^^^^^^^^^^^^^^^^^^^^^^^^
  File "/home/adane/snap/code/190/.local/share/virtualenvs/Backend-OTU7wIHD/lib/python3.12/site-packages/django/views/decorators/csrf.py", line 65, in _view_wrapper
    return view_func(request, *args, **kwargs)
           ^^^^^^^^^^^^^^^^^^^^^^^^^^^^^^^^^^^
  File "/home/adane/snap/code/190/.local/share/virtualenvs/Backend-OTU7wIHD/lib/python3.12/site-packages/rest_framework/viewsets.py", line 125, in view
    return self.dispatch(request, *args, **kwargs)
           ^^^^^^^^^^^^^^^^^^^^^^^^^^^^^^^^^^^^^^^
  File "/home/adane/snap/code/190/.local/share/virtualenvs/Backend-OTU7wIHD/lib/python3.12/site-packages/rest_framework/views.py", line 515, in dispatch
    response = self.handle_exception(exc)
               ^^^^^^^^^^^^^^^^^^^^^^^^^^
  File "/home/adane/snap/code/190/.local/share/virtualenvs/Backend-OTU7wIHD/lib/python3.12/site-packages/rest_framework/views.py", line 475, in handle_exception
    self.raise_uncaught_exception(exc)
  File "/home/adane/snap/code/190/.local/share/virtualenvs/Backend-OTU7wIHD/lib/python3.12/site-packages/rest_framework/views.py", line 486, in raise_uncaught_exception
    raise exc
  File "/home/adane/snap/code/190/.local/share/virtualenvs/Backend-OTU7wIHD/lib/python3.12/site-packages/rest_framework/views.py", line 512, in dispatch
    response = handler(request, *args, **kwargs)
               ^^^^^^^^^^^^^^^^^^^^^^^^^^^^^^^^^
  File "/home/adane/snap/code/190/.local/share/virtualenvs/Backend-OTU7wIHD/lib/python3.12/site-packages/rest_framework/mixins.py", line 19, in create
    self.perform_create(serializer)
  File "/home/adane/Repository/ConnectX/Backend/connectx_backend/products/views.py", line 191, in perform_create
    serializer.save(owner=self.request.user.tenant,)
  File "/home/adane/snap/code/190/.local/share/virtualenvs/Backend-OTU7wIHD/lib/python3.12/site-packages/rest_framework/serializers.py", line 210, in save
    self.instance = self.create(validated_data)
                    ^^^^^^^^^^^^^^^^^^^^^^^^^^^
  File "/home/adane/snap/code/190/.local/share/virtualenvs/Backend-OTU7wIHD/lib/python3.12/site-packages/rest_framework/serializers.py", line 991, in create
    instance = ModelClass._default_manager.create(**validated_data)
               ^^^^^^^^^^^^^^^^^^^^^^^^^^^^^^^^^^^^^^^^^^^^^^^^^^^^
  File "/home/adane/snap/code/190/.local/share/virtualenvs/Backend-OTU7wIHD/lib/python3.12/site-packages/django/db/models/manager.py", line 87, in manager_method
    return getattr(self.get_queryset(), name)(*args, **kwargs)
           ^^^^^^^^^^^^^^^^^^^^^^^^^^^^^^^^^^^^^^^^^^^^^^^^^^^
  File "/home/adane/snap/code/190/.local/share/virtualenvs/Backend-OTU7wIHD/lib/python3.12/site-packages/django/db/models/query.py", line 663, in create
    obj.save(force_insert=True, using=self.db)
  File "/home/adane/Repository/ConnectX/Backend/connectx_backend/products/models.py", line 41, in save
    super().save(*args, **kwargs)
  File "/home/adane/snap/code/190/.local/share/virtualenvs/Backend-OTU7wIHD/lib/python3.12/site-packages/django/db/models/base.py", line 902, in save
    self.save_base(
  File "/home/adane/snap/code/190/.local/share/virtualenvs/Backend-OTU7wIHD/lib/python3.12/site-packages/django/db/models/base.py", line 1008, in save_base
    updated = self._save_table(
              ^^^^^^^^^^^^^^^^^
  File "/home/adane/snap/code/190/.local/share/virtualenvs/Backend-OTU7wIHD/lib/python3.12/site-packages/django/db/models/base.py", line 1169, in _save_table
    results = self._do_insert(
              ^^^^^^^^^^^^^^^^
  File "/home/adane/snap/code/190/.local/share/virtualenvs/Backend-OTU7wIHD/lib/python3.12/site-packages/django/db/models/base.py", line 1210, in _do_insert
    return manager._insert(
           ^^^^^^^^^^^^^^^^
  File "/home/adane/snap/code/190/.local/share/virtualenvs/Backend-OTU7wIHD/lib/python3.12/site-packages/django/db/models/manager.py", line 87, in manager_method
    return getattr(self.get_queryset(), name)(*args, **kwargs)
           ^^^^^^^^^^^^^^^^^^^^^^^^^^^^^^^^^^^^^^^^^^^^^^^^^^^
  File "/home/adane/snap/code/190/.local/share/virtualenvs/Backend-OTU7wIHD/lib/python3.12/site-packages/django/db/models/query.py", line 1854, in _insert
    return query.get_compiler(using=using).execute_sql(returning_fields)
           ^^^^^^^^^^^^^^^^^^^^^^^^^^^^^^^^^^^^^^^^^^^^^^^^^^^^^^^^^^^^^
  File "/home/adane/snap/code/190/.local/share/virtualenvs/Backend-OTU7wIHD/lib/python3.12/site-packages/django/db/models/sql/compiler.py", line 1881, in execute_sql
    cursor.execute(sql, params)
  File "/home/adane/snap/code/190/.local/share/virtualenvs/Backend-OTU7wIHD/lib/python3.12/site-packages/django/db/backends/utils.py", line 122, in execute
    return super().execute(sql, params)
           ^^^^^^^^^^^^^^^^^^^^^^^^^^^^
  File "/home/adane/snap/code/190/.local/share/virtualenvs/Backend-OTU7wIHD/lib/python3.12/site-packages/django/db/backends/utils.py", line 79, in execute
    return self._execute_with_wrappers(
           ^^^^^^^^^^^^^^^^^^^^^^^^^^^^
  File "/home/adane/snap/code/190/.local/share/virtualenvs/Backend-OTU7wIHD/lib/python3.12/site-packages/django/db/backends/utils.py", line 92, in _execute_with_wrappers
    return executor(sql, params, many, context)
           ^^^^^^^^^^^^^^^^^^^^^^^^^^^^^^^^^^^^
  File "/home/adane/snap/code/190/.local/share/virtualenvs/Backend-OTU7wIHD/lib/python3.12/site-packages/django/db/backends/utils.py", line 100, in _execute
    with self.db.wrap_database_errors:
  File "/home/adane/snap/code/190/.local/share/virtualenvs/Backend-OTU7wIHD/lib/python3.12/site-packages/django/db/utils.py", line 91, in __exit__
    raise dj_exc_value.with_traceback(traceback) from exc_value
  File "/home/adane/snap/code/190/.local/share/virtualenvs/Backend-OTU7wIHD/lib/python3.12/site-packages/django/db/backends/utils.py", line 105, in _execute
    return self.cursor.execute(sql, params)
           ^^^^^^^^^^^^^^^^^^^^^^^^^^^^^^^^
django.db.utils.IntegrityError: null value in column "category_id" of relation "products_product" violates not-null constraint
DETAIL:  Failing row contains (2990d0a3-ee9f-4eb1-9646-44874205013b, SKU-001, Smartphone X, 500.00, 20.00, 600.00, 100, t, Latest model with advanced features., , [], , {}, , https://example.com/image.jpg, ["https://example.com/image1.jpg", "https://example.com/image2.j..., ["Black", "White"], ["64GB", "128GB"], 0, 0, 0, 2025-05-04 08:54:21.611227+00, 2025-05-04 08:54:21.611279+00, null, 06cbdc10-c1a0-4e24-8744-dd237b65be43).

"POST /api/products/ HTTP/1.1" 500 32076
Internal Server Error: /api/products/
Traceback (most recent call last):
  File "/home/adane/snap/code/190/.local/share/virtualenvs/Backend-OTU7wIHD/lib/python3.12/site-packages/django/db/backends/utils.py", line 105, in _execute
    return self.cursor.execute(sql, params)
           ^^^^^^^^^^^^^^^^^^^^^^^^^^^^^^^^
psycopg2.errors.NotNullViolation: null value in column "category_id" of relation "products_product" violates not-null constraint
DETAIL:  Failing row contains (acc99b55-c22b-4186-8a7e-de9a7f9e5205, SKU-001, Smartphone X, 500.00, 20.00, 600.00, 100, t, Latest model with advanced features., , [], , {}, , https://example.com/image.jpg, ["https://example.com/image1.jpg", "https://example.com/image2.j..., ["Black", "White"], ["64GB", "128GB"], 0, 0, 0, 2025-05-04 08:54:47.021703+00, 2025-05-04 08:54:47.021734+00, null, 06cbdc10-c1a0-4e24-8744-dd237b65be43).


The above exception was the direct cause of the following exception:

Traceback (most recent call last):
  File "/home/adane/snap/code/190/.local/share/virtualenvs/Backend-OTU7wIHD/lib/python3.12/site-packages/django/core/handlers/exception.py", line 55, in inner
    response = get_response(request)
               ^^^^^^^^^^^^^^^^^^^^^
  File "/home/adane/snap/code/190/.local/share/virtualenvs/Backend-OTU7wIHD/lib/python3.12/site-packages/django/core/handlers/base.py", line 197, in _get_response
    response = wrapped_callback(request, *callback_args, **callback_kwargs)
               ^^^^^^^^^^^^^^^^^^^^^^^^^^^^^^^^^^^^^^^^^^^^^^^^^^^^^^^^^^^^
  File "/home/adane/snap/code/190/.local/share/virtualenvs/Backend-OTU7wIHD/lib/python3.12/site-packages/django/views/decorators/csrf.py", line 65, in _view_wrapper
    return view_func(request, *args, **kwargs)
           ^^^^^^^^^^^^^^^^^^^^^^^^^^^^^^^^^^^
  File "/home/adane/snap/code/190/.local/share/virtualenvs/Backend-OTU7wIHD/lib/python3.12/site-packages/rest_framework/viewsets.py", line 125, in view
    return self.dispatch(request, *args, **kwargs)
           ^^^^^^^^^^^^^^^^^^^^^^^^^^^^^^^^^^^^^^^
  File "/home/adane/snap/code/190/.local/share/virtualenvs/Backend-OTU7wIHD/lib/python3.12/site-packages/rest_framework/views.py", line 515, in dispatch
    response = self.handle_exception(exc)
               ^^^^^^^^^^^^^^^^^^^^^^^^^^
  File "/home/adane/snap/code/190/.local/share/virtualenvs/Backend-OTU7wIHD/lib/python3.12/site-packages/rest_framework/views.py", line 475, in handle_exception
    self.raise_uncaught_exception(exc)
  File "/home/adane/snap/code/190/.local/share/virtualenvs/Backend-OTU7wIHD/lib/python3.12/site-packages/rest_framework/views.py", line 486, in raise_uncaught_exception
    raise exc
  File "/home/adane/snap/code/190/.local/share/virtualenvs/Backend-OTU7wIHD/lib/python3.12/site-packages/rest_framework/views.py", line 512, in dispatch
    response = handler(request, *args, **kwargs)
               ^^^^^^^^^^^^^^^^^^^^^^^^^^^^^^^^^
  File "/home/adane/snap/code/190/.local/share/virtualenvs/Backend-OTU7wIHD/lib/python3.12/site-packages/rest_framework/mixins.py", line 19, in create
    self.perform_create(serializer)
  File "/home/adane/Repository/ConnectX/Backend/connectx_backend/products/views.py", line 191, in perform_create
    serializer.save(owner=self.request.user.tenant,)
  File "/home/adane/snap/code/190/.local/share/virtualenvs/Backend-OTU7wIHD/lib/python3.12/site-packages/rest_framework/serializers.py", line 210, in save
    self.instance = self.create(validated_data)
                    ^^^^^^^^^^^^^^^^^^^^^^^^^^^
  File "/home/adane/snap/code/190/.local/share/virtualenvs/Backend-OTU7wIHD/lib/python3.12/site-packages/rest_framework/serializers.py", line 991, in create
    instance = ModelClass._default_manager.create(**validated_data)
               ^^^^^^^^^^^^^^^^^^^^^^^^^^^^^^^^^^^^^^^^^^^^^^^^^^^^
  File "/home/adane/snap/code/190/.local/share/virtualenvs/Backend-OTU7wIHD/lib/python3.12/site-packages/django/db/models/manager.py", line 87, in manager_method
    return getattr(self.get_queryset(), name)(*args, **kwargs)
           ^^^^^^^^^^^^^^^^^^^^^^^^^^^^^^^^^^^^^^^^^^^^^^^^^^^
  File "/home/adane/snap/code/190/.local/share/virtualenvs/Backend-OTU7wIHD/lib/python3.12/site-packages/django/db/models/query.py", line 663, in create
    obj.save(force_insert=True, using=self.db)
  File "/home/adane/Repository/ConnectX/Backend/connectx_backend/products/models.py", line 41, in save
    super().save(*args, **kwargs)
  File "/home/adane/snap/code/190/.local/share/virtualenvs/Backend-OTU7wIHD/lib/python3.12/site-packages/django/db/models/base.py", line 902, in save
    self.save_base(
  File "/home/adane/snap/code/190/.local/share/virtualenvs/Backend-OTU7wIHD/lib/python3.12/site-packages/django/db/models/base.py", line 1008, in save_base
    updated = self._save_table(
              ^^^^^^^^^^^^^^^^^
  File "/home/adane/snap/code/190/.local/share/virtualenvs/Backend-OTU7wIHD/lib/python3.12/site-packages/django/db/models/base.py", line 1169, in _save_table
    results = self._do_insert(
              ^^^^^^^^^^^^^^^^
  File "/home/adane/snap/code/190/.local/share/virtualenvs/Backend-OTU7wIHD/lib/python3.12/site-packages/django/db/models/base.py", line 1210, in _do_insert
    return manager._insert(
           ^^^^^^^^^^^^^^^^
  File "/home/adane/snap/code/190/.local/share/virtualenvs/Backend-OTU7wIHD/lib/python3.12/site-packages/django/db/models/manager.py", line 87, in manager_method
    return getattr(self.get_queryset(), name)(*args, **kwargs)
           ^^^^^^^^^^^^^^^^^^^^^^^^^^^^^^^^^^^^^^^^^^^^^^^^^^^
  File "/home/adane/snap/code/190/.local/share/virtualenvs/Backend-OTU7wIHD/lib/python3.12/site-packages/django/db/models/query.py", line 1854, in _insert
    return query.get_compiler(using=using).execute_sql(returning_fields)
           ^^^^^^^^^^^^^^^^^^^^^^^^^^^^^^^^^^^^^^^^^^^^^^^^^^^^^^^^^^^^^
  File "/home/adane/snap/code/190/.local/share/virtualenvs/Backend-OTU7wIHD/lib/python3.12/site-packages/django/db/models/sql/compiler.py", line 1881, in execute_sql
    cursor.execute(sql, params)
  File "/home/adane/snap/code/190/.local/share/virtualenvs/Backend-OTU7wIHD/lib/python3.12/site-packages/django/db/backends/utils.py", line 122, in execute
    return super().execute(sql, params)
           ^^^^^^^^^^^^^^^^^^^^^^^^^^^^
  File "/home/adane/snap/code/190/.local/share/virtualenvs/Backend-OTU7wIHD/lib/python3.12/site-packages/django/db/backends/utils.py", line 79, in execute
    return self._execute_with_wrappers(
           ^^^^^^^^^^^^^^^^^^^^^^^^^^^^
  File "/home/adane/snap/code/190/.local/share/virtualenvs/Backend-OTU7wIHD/lib/python3.12/site-packages/django/db/backends/utils.py", line 92, in _execute_with_wrappers
    return executor(sql, params, many, context)
           ^^^^^^^^^^^^^^^^^^^^^^^^^^^^^^^^^^^^
  File "/home/adane/snap/code/190/.local/share/virtualenvs/Backend-OTU7wIHD/lib/python3.12/site-packages/django/db/backends/utils.py", line 100, in _execute
    with self.db.wrap_database_errors:
  File "/home/adane/snap/code/190/.local/share/virtualenvs/Backend-OTU7wIHD/lib/python3.12/site-packages/django/db/utils.py", line 91, in __exit__
    raise dj_exc_value.with_traceback(traceback) from exc_value
  File "/home/adane/snap/code/190/.local/share/virtualenvs/Backend-OTU7wIHD/lib/python3.12/site-packages/django/db/backends/utils.py", line 105, in _execute
    return self.cursor.execute(sql, params)
           ^^^^^^^^^^^^^^^^^^^^^^^^^^^^^^^^
django.db.utils.IntegrityError: null value in column "category_id" of relation "products_product" violates not-null constraint
DETAIL:  Failing row contains (acc99b55-c22b-4186-8a7e-de9a7f9e5205, SKU-001, Smartphone X, 500.00, 20.00, 600.00, 100, t, Latest model with advanced features., , [], , {}, , https://example.com/image.jpg, ["https://example.com/image1.jpg", "https://example.com/image2.j..., ["Black", "White"], ["64GB", "128GB"], 0, 0, 0, 2025-05-04 08:54:47.021703+00, 2025-05-04 08:54:47.021734+00, null, 06cbdc10-c1a0-4e24-8744-dd237b65be43).

